{
 "cells": [
  {
   "cell_type": "markdown",
   "metadata": {},
   "source": [
    "# Feilmeldinger i Python 101"
   ]
  },
  {
   "cell_type": "markdown",
   "metadata": {},
   "source": [
    "## Læringsmål:\n",
    "\n",
    "* Lære å gjenkjenne de typiske feilmeldingene i Python og rette opp i feilen."
   ]
  },
  {
   "cell_type": "markdown",
   "metadata": {},
   "source": [
    "## Feilmeldingstyper"
   ]
  },
  {
   "cell_type": "markdown",
   "metadata": {},
   "source": [
    "### `NameError`\n",
    "\n",
    "Noen ganger kan vi skrive kode, og så får vi får vi en feilmelding som dette:\n",
    "\n",
    "```console\n",
    "NameError: name 'a' is not defined\n",
    "```"
   ]
  },
  {
   "cell_type": "markdown",
   "metadata": {},
   "source": [
    "Denne feilmeldingen skyldes rett og slett bare at variabelen ikke har blitt definert av oss som brukere. For en variabel med navn `a` er dette en veldig opplagt feil å møte og fikse. Men dersom vi i stedet har noe sånt som dette"
   ]
  },
  {
   "cell_type": "code",
   "execution_count": 2,
   "metadata": {},
   "outputs": [
    {
     "ename": "NameError",
     "evalue": "name 'antall_melddinger' is not defined",
     "output_type": "error",
     "traceback": [
      "\u001b[0;31m---------------------------------------------------------------------------\u001b[0m",
      "\u001b[0;31mNameError\u001b[0m                                 Traceback (most recent call last)",
      "Cell \u001b[0;32mIn[2], line 3\u001b[0m\n\u001b[1;32m      1\u001b[0m antall_meldinger \u001b[39m=\u001b[39m \u001b[39m20\u001b[39m\n\u001b[0;32m----> 3\u001b[0m \u001b[39mprint\u001b[39m(\u001b[39mf\u001b[39m\u001b[39m\"\u001b[39m\u001b[39m{\u001b[39;00mantall_melddinger\u001b[39m \u001b[39m\u001b[39m= }\u001b[39;00m\u001b[39m\"\u001b[39m)\n",
      "\u001b[0;31mNameError\u001b[0m: name 'antall_melddinger' is not defined"
     ]
    }
   ],
   "source": [
    "antall_meldinger = 20\n",
    "\n",
    "print(f\"{antall_melddinger = }\")"
   ]
  },
  {
   "cell_type": "markdown",
   "metadata": {},
   "source": [
    "så skyldes det oftest bare en skrivefeil fra vår side. Her har vi skrevet `antall_melddinger` i stedet for `antall_meldinger` som er grunnen til at Python kaster ut en `NameError`. "
   ]
  },
  {
   "cell_type": "markdown",
   "metadata": {},
   "source": [
    "### `SyntaxError`\n",
    "\n",
    "En `SyntaxError` er en feil der vi bryter reglene til Python med tanke på skrivemåte, eller da *syntaksen* som Python tillatter. La oss se på noen eksempler:"
   ]
  },
  {
   "cell_type": "markdown",
   "metadata": {},
   "source": [
    "### Eksempel 1: Manglende kolon"
   ]
  },
  {
   "cell_type": "code",
   "execution_count": 4,
   "metadata": {},
   "outputs": [
    {
     "ename": "SyntaxError",
     "evalue": "expected ':' (859882524.py, line 1)",
     "output_type": "error",
     "traceback": [
      "\u001b[0;36m  Cell \u001b[0;32mIn[4], line 1\u001b[0;36m\u001b[0m\n\u001b[0;31m    for i in range(3)\u001b[0m\n\u001b[0m                     ^\u001b[0m\n\u001b[0;31mSyntaxError\u001b[0m\u001b[0;31m:\u001b[0m expected ':'\n"
     ]
    }
   ],
   "source": [
    "for i in range(3)\n",
    "    print(i)"
   ]
  },
  {
   "cell_type": "markdown",
   "metadata": {},
   "source": [
    "Her kaster Python ut en `SyntaxError` og forteller oss at den forventet en `:` og peker på hvor den skal stå. Alt vi trenger å gjøre, er å slenge inn en `:`, så er det fikset."
   ]
  },
  {
   "cell_type": "code",
   "execution_count": 5,
   "metadata": {},
   "outputs": [
    {
     "name": "stdout",
     "output_type": "stream",
     "text": [
      "0\n",
      "1\n",
      "2\n"
     ]
    }
   ],
   "source": [
    "for i in range(3):\n",
    "    print(i)"
   ]
  },
  {
   "cell_type": "markdown",
   "metadata": {},
   "source": [
    "### Eksempel 2: Manglende parenteser\n",
    "\n",
    "Noen ganger mangler vi parenteser i koden vår. Da kan vi møte på noe sånt som dette:"
   ]
  },
  {
   "cell_type": "code",
   "execution_count": 7,
   "metadata": {},
   "outputs": [
    {
     "ename": "SyntaxError",
     "evalue": "incomplete input (2838798626.py, line 1)",
     "output_type": "error",
     "traceback": [
      "\u001b[0;36m  Cell \u001b[0;32mIn[7], line 1\u001b[0;36m\u001b[0m\n\u001b[0;31m    a = (2 + 3) / (4 * 5 - 1\u001b[0m\n\u001b[0m                            ^\u001b[0m\n\u001b[0;31mSyntaxError\u001b[0m\u001b[0;31m:\u001b[0m incomplete input\n"
     ]
    }
   ],
   "source": [
    "a = (2 + 3) / (4 * 5 - 1"
   ]
  },
  {
   "cell_type": "markdown",
   "metadata": {},
   "source": [
    "Her får vi igjen en `SyntaxError`, og vi blir fortalt at vi mangler noe i koden vi har skrevet. Her må vi selv forstå at det er en `)` som mangler, men vi får i det minste vite akkurat hvor feil er. La oss sette på en `)` der pila peker, så er alt i orden:"
   ]
  },
  {
   "cell_type": "code",
   "execution_count": 8,
   "metadata": {},
   "outputs": [],
   "source": [
    "a = (2 + 3) / (4 * 5 - 1)"
   ]
  },
  {
   "cell_type": "markdown",
   "metadata": {},
   "source": [
    "### `TypeError`\n",
    "\n",
    "Noen ganger får vi `TypeError` i fleisen, og dette betyr bare at vi har brukt en funksjon som ikke godtar den datatypen vi har gitt den. "
   ]
  },
  {
   "cell_type": "markdown",
   "metadata": {},
   "source": [
    "### Eksempel 1: `range`-funksjonen\n",
    "\n",
    "La oss se på et eksempel med `range`-funksjonen som vi ofte bruker i en `for`-løkke:"
   ]
  },
  {
   "cell_type": "code",
   "execution_count": 10,
   "metadata": {},
   "outputs": [
    {
     "ename": "TypeError",
     "evalue": "'float' object cannot be interpreted as an integer",
     "output_type": "error",
     "traceback": [
      "\u001b[0;31m---------------------------------------------------------------------------\u001b[0m",
      "\u001b[0;31mTypeError\u001b[0m                                 Traceback (most recent call last)",
      "Cell \u001b[0;32mIn[10], line 2\u001b[0m\n\u001b[1;32m      1\u001b[0m n \u001b[39m=\u001b[39m \u001b[39m3.0\u001b[39m\n\u001b[0;32m----> 2\u001b[0m \u001b[39mfor\u001b[39;00m i \u001b[39min\u001b[39;00m \u001b[39mrange\u001b[39;49m(n):\n\u001b[1;32m      3\u001b[0m     \u001b[39mprint\u001b[39m(i)\n",
      "\u001b[0;31mTypeError\u001b[0m: 'float' object cannot be interpreted as an integer"
     ]
    }
   ],
   "source": [
    "n = 3.0\n",
    "for i in range(n):\n",
    "    print(i)"
   ]
  },
  {
   "cell_type": "markdown",
   "metadata": {},
   "source": [
    "Her får vi `TypeError` og blir fortalt at vi har sendt inn et `float`-objekt til `range`. I tillegg står det at den ikke kan tolkes som en integer (heltall, `int`). Vi må altså bare endre `n` til en `int`, så er alt i orden:"
   ]
  },
  {
   "cell_type": "code",
   "execution_count": 11,
   "metadata": {},
   "outputs": [
    {
     "name": "stdout",
     "output_type": "stream",
     "text": [
      "0\n",
      "1\n",
      "2\n"
     ]
    }
   ],
   "source": [
    "n = 3\n",
    "for i in range(n):\n",
    "    print(i)"
   ]
  },
  {
   "cell_type": "markdown",
   "metadata": {},
   "source": [
    "### `ValueError`\n",
    "\n",
    "En `ValueError` får vi ofte når vi bruker matematiske funksjoner der vi sender inn argumenter som ikke gir mening. La oss se på et eksempel:\n",
    "\n",
    "#### Eksempel 1: Negative tall i `sqrt`\n"
   ]
  },
  {
   "cell_type": "code",
   "execution_count": 13,
   "metadata": {},
   "outputs": [
    {
     "ename": "ValueError",
     "evalue": "math domain error",
     "output_type": "error",
     "traceback": [
      "\u001b[0;31m---------------------------------------------------------------------------\u001b[0m",
      "\u001b[0;31mValueError\u001b[0m                                Traceback (most recent call last)",
      "Cell \u001b[0;32mIn[13], line 3\u001b[0m\n\u001b[1;32m      1\u001b[0m \u001b[39mimport\u001b[39;00m \u001b[39mmath\u001b[39;00m\n\u001b[0;32m----> 3\u001b[0m math\u001b[39m.\u001b[39;49msqrt(\u001b[39m-\u001b[39;49m\u001b[39m2\u001b[39;49m)\n",
      "\u001b[0;31mValueError\u001b[0m: math domain error"
     ]
    }
   ],
   "source": [
    "import math\n",
    "\n",
    "math.sqrt(-2)"
   ]
  },
  {
   "cell_type": "markdown",
   "metadata": {},
   "source": [
    "Her får vi `ValueError: math domain error`, som forteller oss at vi har sendt inn en verdi av $x$, der rotfunksjonen ikke er definert (\"domain\" betyr det samme som definisjonsmengde)."
   ]
  }
 ],
 "metadata": {
  "kernelspec": {
   "display_name": "Python 3",
   "language": "python",
   "name": "python3"
  },
  "language_info": {
   "codemirror_mode": {
    "name": "ipython",
    "version": 3
   },
   "file_extension": ".py",
   "mimetype": "text/x-python",
   "name": "python",
   "nbconvert_exporter": "python",
   "pygments_lexer": "ipython3",
   "version": "3.11.4"
  },
  "orig_nbformat": 4
 },
 "nbformat": 4,
 "nbformat_minor": 2
}
