Traceback (most recent call last):
  File "/opt/homebrew/lib/python3.11/site-packages/jupyter_cache/executors/utils.py", line 58, in single_nb_execution
    executenb(
  File "/opt/homebrew/lib/python3.11/site-packages/nbclient/client.py", line 1265, in execute
    return NotebookClient(nb=nb, resources=resources, km=km, **kwargs).execute()
           ^^^^^^^^^^^^^^^^^^^^^^^^^^^^^^^^^^^^^^^^^^^^^^^^^^^^^^^^^^^^^^^^^^^^^
  File "/opt/homebrew/lib/python3.11/site-packages/jupyter_core/utils/__init__.py", line 166, in wrapped
    return loop.run_until_complete(inner)
           ^^^^^^^^^^^^^^^^^^^^^^^^^^^^^^
  File "/opt/homebrew/Cellar/python@3.11/3.11.3/Frameworks/Python.framework/Versions/3.11/lib/python3.11/asyncio/base_events.py", line 653, in run_until_complete
    return future.result()
           ^^^^^^^^^^^^^^^
  File "/opt/homebrew/lib/python3.11/site-packages/nbclient/client.py", line 703, in async_execute
    await self.async_execute_cell(
  File "/opt/homebrew/lib/python3.11/site-packages/nbclient/client.py", line 1021, in async_execute_cell
    await self._check_raise_for_error(cell, cell_index, exec_reply)
  File "/opt/homebrew/lib/python3.11/site-packages/nbclient/client.py", line 915, in _check_raise_for_error
    raise CellExecutionError.from_cell_and_msg(cell, exec_reply_content)
nbclient.exceptions.CellExecutionError: An error occurred while executing the following cell:
------------------
def test_f():
    x = 2
    forventet_verdi = 7
    if f(x) != forventet_verdi:
        raise ValueError("Det er noe galt med funksjonen f(x). Den skal returnere 7 n√•r x=2.")
test_f()
------------------

[0;31m---------------------------------------------------------------------------[0m
[0;31mValueError[0m                                Traceback (most recent call last)
Cell [0;32mIn[2], line 6[0m
[1;32m      4[0m     [38;5;28;01mif[39;00m f(x) [38;5;241m!=[39m forventet_verdi:
[1;32m      5[0m         [38;5;28;01mraise[39;00m [38;5;167;01mValueError[39;00m([38;5;124m"[39m[38;5;124mDet er noe galt med funksjonen f(x). Den skal returnere 7 n√•r x=2.[39m[38;5;124m"[39m)
[0;32m----> 6[0m [43mtest_f[49m[43m([49m[43m)[49m

Cell [0;32mIn[2], line 5[0m, in [0;36mtest_f[0;34m()[0m
[1;32m      3[0m forventet_verdi [38;5;241m=[39m [38;5;241m7[39m
[1;32m      4[0m [38;5;28;01mif[39;00m f(x) [38;5;241m!=[39m forventet_verdi:
[0;32m----> 5[0m     [38;5;28;01mraise[39;00m [38;5;167;01mValueError[39;00m([38;5;124m"[39m[38;5;124mDet er noe galt med funksjonen f(x). Den skal returnere 7 n√•r x=2.[39m[38;5;124m"[39m)

[0;31mValueError[0m: Det er noe galt med funksjonen f(x). Den skal returnere 7 n√•r x=2.
ValueError: Det er noe galt med funksjonen f(x). Den skal returnere 7 n√•r x=2.

